<?xml version='1.0' encoding='utf-8'?>
<robot xmlns:xacro="http://www.ros.org/wiki/xacro" name="robot">
  <xacro:macro name="robot_arm" params="arm_id:='robot' description_pkg:='robot_description' connected_to:='' xyz:='0 0 0' rpy:='0 0 0'">
    <xacro:unless value="${not connected_to}">
      <joint name="${arm_id}_joint_${connected_to}" type="fixed">
        <parent link="${connected_to}"/>
        <child link="${arm_id}_link0"/>
        <origin rpy="${rpy}" xyz="${xyz}"/>
      </joint>
    </xacro:unless>

    <!-- bottom -->
    <link name="${arm_id}_bottom"/>
    <joint name="bottom_joint" type="fixed">
      <origin xyz="0 0 0.075" rpy="0 0 0" />
      <parent link="${arm_id}_bottom" />
      <child link="${arm_id}_link0" />
      <axis xyz="0 0 1" />
    </joint>

    <!-- link0 -->
    <link name="${arm_id}_link0">
      <visual>
        <geometry>
          <mesh filename="package://${description_pkg}/meshes/visual/link0.dae"/>
        </geometry>
      </visual>
      <collision>
        <geometry>
          <mesh filename="package://${description_pkg}/meshes/collision/link0.stl"/>
        </geometry>
      </collision>

      <inertial>
        <origin xyz="0 0 0" rpy="0 0 0" />
        <mass value="165.7" />
        <inertia ixx="0.3" ixy="0.0" ixz="0.0" iyy="0.3" iyz="0.0" izz="0.3" />
      </inertial>
    </link>



    <!-- link1 -->
    <link name="${arm_id}_link1">
      <visual>
        <geometry>
          <mesh filename="package://${description_pkg}/meshes/visual/link1.dae"/>
        </geometry>
      </visual>
      <collision>
        <geometry>
          <mesh filename="package://${description_pkg}/meshes/collision/link1.stl"/>
        </geometry>
      </collision>

      <inertial>
        <origin xyz="0 0 0" rpy="0 0 0" />
        <mass value="7.92" />
        <inertia ixx="0.3" ixy="0.0" ixz="0.0" iyy="0.3" iyz="0.0" izz="0.3" />
      </inertial>
    </link>
    <!-- lower, upper, speed limit?  -->
    <joint name="${arm_id}_joint1" type="prismatic">
      <safety_controller k_position="100.0" k_velocity="40.0" soft_lower_limit="0.0" soft_upper_limit="2.15"/>
      <origin rpy="0 0 0" xyz="0.157 0 0.324"/>
      <parent link="${arm_id}_link0"/>
      <child link="${arm_id}_link1"/>
      <axis xyz="0 0 1"/>
      <limit effort="1222" lower="0.0" upper="2.15" velocity="0.3"/>
    </joint>

    <!-- link2 -->
    <link name="${arm_id}_link2">
      <visual>
        <geometry>
          <mesh filename="package://${description_pkg}/meshes/visual/link2.dae"/>
        </geometry>
      </visual>
      <collision>
        <geometry>
          <mesh filename="package://${description_pkg}/meshes/collision/link2.stl"/>
        </geometry>
      </collision>

      <inertial>
        <origin xyz="0 0 0" rpy="0 0 0" />
        <mass value="17.08" />
        <inertia ixx="0.3" ixy="0.0" ixz="0.0" iyy="0.3" iyz="0.0" izz="0.3" />
      </inertial>
    </link>
    <!-- lower, upper, speed limit?  -->
    <joint name="${arm_id}_joint2" type="revolute">
      <safety_controller k_position="100.0" k_velocity="40.0" soft_lower_limit="-1.66" soft_upper_limit="1.66"/>
      <origin rpy="0 0 0" xyz="0 0 0.094"/>
      <parent link="${arm_id}_link1"/>
      <child link="${arm_id}_link2"/>
      <axis xyz="0 0 1"/>
      <limit effort="160" lower="-1.9" upper="1.9" velocity="4.147"/>
    </joint>

    <!-- link3 -->
    <link name="${arm_id}_link3">
      <visual>
        <geometry>
          <mesh filename="package://${description_pkg}/meshes/visual/link3.dae"/>
        </geometry>
      </visual>
      <collision>
        <geometry>
          <mesh filename="package://${description_pkg}/meshes/collision/link3.stl"/>
        </geometry>
      </collision>

      <inertial>
        <origin xyz="0 0 0" rpy="0 0 0" />
        <mass value="7.08" />
        <inertia ixx="0.3" ixy="0.0" ixz="0.0" iyy="0.3" iyz="0.0" izz="0.3" />
      </inertial>
      <!-- end for simulation -->
    </link>
    <!-- lower, upper, speed limit?  -->
    <joint name="${arm_id}_joint3" type="revolute">
      <safety_controller k_position="100.0" k_velocity="40.0" soft_lower_limit="-2.6" soft_upper_limit="2.6"/>
      <origin rpy="0 0 0" xyz="0.500 0 0.1833"/>
      <parent link="${arm_id}_link2"/>
      <child link="${arm_id}_link3"/>
      <axis xyz="0 0 1"/>
      <limit effort="84" lower="-2.6" upper="2.6" velocity="3.665"/>
    </joint>

    <!-- link4 -->
    <link name="${arm_id}_link4">
      <visual>
        <geometry>
          <mesh filename="package://${description_pkg}/meshes/visual/link4.dae"/>
        </geometry>
      </visual>
      <collision>
        <geometry>
          <mesh filename="package://${description_pkg}/meshes/collision/link4.stl"/>
        </geometry>
      </collision>
      <!-- mass? -->
      <inertial>
        <origin xyz="0 0 0" rpy="0 0 0" />
        <mass value="8.28" />
        <inertia ixx="0.3" ixy="0.0" ixz="0.0" iyy="0.3" iyz="0.0" izz="0.3" />
      </inertial>
      <!-- end for simulation -->
    </link>
    <!-- lower, upper, speed limit?  -->
    <joint name="${arm_id}_joint4" type="revolute">
      <safety_controller k_position="100.0" k_velocity="40.0" soft_lower_limit="-3.32" soft_upper_limit="3.32"/>
      <origin rpy="0 0 ${pi/2}" xyz="0.500 0 -0.187"/>
      <parent link="${arm_id}_link3"/>
      <child link="${arm_id}_link4"/>
      <axis xyz="0 0 1"/>
      <limit effort="30" lower="-2" upper="2" velocity="4.974"/>
    </joint>

    <!-- link5 -->
    <link name="${arm_id}_link5">
      <visual>
        <geometry>
          <mesh filename="package://${description_pkg}/meshes/visual/link5.dae"/>
        </geometry>
      </visual>
      <collision>
        <geometry>
          <mesh filename="package://${description_pkg}/meshes/collision/link5.stl"/>
        </geometry>
      </collision>
      <!-- mass? -->
      <inertial>
        <origin xyz="0 0 0" rpy="0 0 0" />
        <mass value="5.4" />
        <inertia ixx="0.3" ixy="0.0" ixz="0.0" iyy="0.3" iyz="0.0" izz="0.3" />
      </inertial>
      <!-- end for simulation -->
    </link>
    <!-- lower, upper, speed limit?  -->
    <joint name="${arm_id}_joint5" type="revolute">
      <safety_controller k_position="100.0" k_velocity="40.0" soft_lower_limit="-1.60" soft_upper_limit="1.85"/>
      <origin rpy="${pi/2} 0 0" xyz="0 0 0"/>
      <parent link="${arm_id}_link4"/>
      <child link="${arm_id}_link5"/>
      <axis xyz="0 0 1"/>
      <limit effort="528" lower="-1.60" upper="1.85" velocity="1.623"/>
    </joint>

    <!-- link6 -->
    <link name="${arm_id}_link6"/>
    <!-- lower, upper, speed limit?  -->
    <joint name="${arm_id}_joint6" type="revolute">
      <safety_controller k_position="100.0" k_velocity="40.0" soft_lower_limit="-3.32" soft_upper_limit="3.32"/>
      <origin rpy="${pi/2} -${pi/2} 0" xyz="0.0 -0.120 0"/>
      <parent link="${arm_id}_link5"/>
      <child link="${arm_id}_link6"/>
      <axis xyz="0 0 1"/>
      <limit effort="84" lower="-2" upper="2" velocity="3.665"/>
    </joint>

    <!-- gripper -->
    <link name="${arm_id}_gripper">
      <visual>
        <geometry>
          <mesh filename="package://${description_pkg}/meshes/visual/gripper.dae"/>
        </geometry>
      </visual>
      <collision>
        <geometry>
          <mesh filename="package://${description_pkg}/meshes/collision/gripper.stl"/>
        </geometry>
      </collision>
      <!-- mass? -->
      <inertial>
        <origin xyz="0 0 0" rpy="0 0 0" />
        <mass value="2.74" />
        <inertia ixx="0.3" ixy="0.0" ixz="0.0" iyy="0.3" iyz="0.0" izz="0.3" />
      </inertial>
    </link>
    <joint name="${arm_id}_joint7" type="fixed">
      <origin rpy="0 0 0" xyz="0.100 0.0 0.047"/>
      <parent link="${arm_id}_link6"/>
      <child link="${arm_id}_gripper"/>
      <axis xyz="0 0 1"/>
    </joint>

    <!-- grasping frame -->
    <link name="tcp"/>
    <joint name="tcp_joint" type="fixed">
      <origin xyz="0 0 0.06887" rpy="0 0 0" />
      <parent link="${arm_id}_gripper" />
      <child link="tcp" />
      <axis xyz="0 0 1" />
    </joint>
  </xacro:macro>
</robot>
