<?xml version="1.0" ?>
<!-- =================================================================================== -->
<!-- |    This document was autogenerated by xacro from robot_arm.urdf.xacro           | -->
<!-- |    EDITING THIS FILE BY HAND IS NOT RECOMMENDED                                 | -->
<!-- =================================================================================== -->
<robot name="robot">
  <!-- for simulation -->
  <!--  <xacro:include filename="$(find franka_description)/robots/panda.gazebo.xacro"/>-->
  <!--  <xacro:include filename="panda.transmission.xacro"/>-->
  <!-- end for simulation -->
  <!-- bottom -->
  <link name="robot_bottom"/>
  <joint name="bottom_joint" type="fixed">
    <origin rpy="0 0 0" xyz="0 0 0.075"/>
    <parent link="robot_bottom"/>
    <child link="robot_link0"/>
    <axis xyz="0 0 1"/>
  </joint>
  <!-- link0 -->
  <link name="robot_link0">
    <visual>
      <geometry>
        <mesh filename="package://robot_description/meshes/visual/link0.dae"/>
      </geometry>
    </visual>
    <collision>
      <geometry>
        <mesh filename="package://robot_description/meshes/collision/link0.stl"/>
      </geometry>
    </collision>
    <inertial>
      <origin rpy="0 0 0" xyz="0 0 0"/>
      <mass value="165.7"/>
      <inertia ixx="0.3" ixy="0.0" ixz="0.0" iyy="0.3" iyz="0.0" izz="0.3"/>
    </inertial>
  </link>
  <!-- link1 -->
  <link name="robot_link1">
    <visual>
      <geometry>
        <mesh filename="package://robot_description/meshes/visual/link1.dae"/>
      </geometry>
    </visual>
    <collision>
      <geometry>
        <mesh filename="package://robot_description/meshes/collision/link1.stl"/>
      </geometry>
    </collision>
    <inertial>
      <origin rpy="0 0 0" xyz="0 0 0"/>
      <mass value="7.92"/>
      <inertia ixx="0.3" ixy="0.0" ixz="0.0" iyy="0.3" iyz="0.0" izz="0.3"/>
    </inertial>
  </link>
  <!-- lower, upper, speed limit?  -->
  <joint name="robot_joint1" type="prismatic">
    <origin rpy="0 0 0" xyz="0.157 0 0.324"/>
    <parent link="robot_link0"/>
    <child link="robot_link1"/>
    <axis xyz="0 0 1"/>
    <limit effort="1222" lower="0.0" upper="2.15" velocity="0.2"/>
  </joint>
  <!-- link2 -->
  <link name="robot_link2">
    <visual>
      <geometry>
        <mesh filename="package://robot_description/meshes/visual/link2.dae"/>
      </geometry>
    </visual>
    <collision>
      <geometry>
        <mesh filename="package://robot_description/meshes/collision/link2.stl"/>
      </geometry>
    </collision>
    <inertial>
      <origin rpy="0 0 0" xyz="0 0 0"/>
      <mass value="17.08"/>
      <inertia ixx="0.3" ixy="0.0" ixz="0.0" iyy="0.3" iyz="0.0" izz="0.3"/>
    </inertial>
  </link>
  <!-- lower, upper, speed limit?  -->
  <joint name="robot_joint2" type="revolute">
    <origin rpy="0 0 0" xyz="0 0 0.094"/>
    <parent link="robot_link1"/>
    <child link="robot_link2"/>
    <axis xyz="0 0 1"/>
    <limit effort="160" lower="-1.9" upper="1.9" velocity="4.147"/>
  </joint>
  <!-- link3 -->
  <link name="robot_link3">
    <visual>
      <geometry>
        <mesh filename="package://robot_description/meshes/visual/link3.dae"/>
      </geometry>
    </visual>
    <collision>
      <geometry>
        <mesh filename="package://robot_description/meshes/collision/link3.stl"/>
      </geometry>
    </collision>
    <inertial>
      <origin rpy="0 0 0" xyz="0 0 0"/>
      <mass value="7.08"/>
      <inertia ixx="0.3" ixy="0.0" ixz="0.0" iyy="0.3" iyz="0.0" izz="0.3"/>
    </inertial>
    <!-- end for simulation -->
  </link>
  <!-- lower, upper, speed limit?  -->
  <joint name="robot_joint3" type="revolute">
    <origin rpy="0 0 0" xyz="0.500 0 0.1833"/>
    <parent link="robot_link2"/>
    <child link="robot_link3"/>
    <axis xyz="0 0 1"/>
    <limit effort="84" lower="-2.6" upper="2.6" velocity="3.665"/>
  </joint>
  <!-- link4 -->
  <link name="robot_link4">
    <visual>
      <geometry>
        <mesh filename="package://robot_description/meshes/visual/link4.dae"/>
      </geometry>
    </visual>
    <collision>
      <geometry>
        <mesh filename="package://robot_description/meshes/collision/link4.stl"/>
      </geometry>
    </collision>
    <!-- mass? -->
    <inertial>
      <origin rpy="0 0 0" xyz="0 0 0"/>
      <mass value="8.28"/>
      <inertia ixx="0.3" ixy="0.0" ixz="0.0" iyy="0.3" iyz="0.0" izz="0.3"/>
    </inertial>
    <!-- end for simulation -->
  </link>
  <!-- lower, upper, speed limit?  -->
  <joint name="robot_joint4" type="revolute">
    <origin rpy="0 0 1.5707963267948966" xyz="0.500 0 -0.187"/>
    <parent link="robot_link3"/>
    <child link="robot_link4"/>
    <axis xyz="0 0 1"/>
    <limit effort="30" lower="-2" upper="2" velocity="4.974"/>
  </joint>
  <!-- link5 -->
  <link name="robot_link5">
    <visual>
      <geometry>
        <mesh filename="package://robot_description/meshes/visual/link5.dae"/>
      </geometry>
    </visual>
    <collision>
      <geometry>
        <mesh filename="package://robot_description/meshes/collision/link5.stl"/>
      </geometry>
    </collision>
    <!-- mass? -->
    <inertial>
      <origin rpy="0 0 0" xyz="0 0 0"/>
      <mass value="5.4"/>
      <inertia ixx="0.3" ixy="0.0" ixz="0.0" iyy="0.3" iyz="0.0" izz="0.3"/>
    </inertial>
    <!-- end for simulation -->
  </link>
  <!-- lower, upper, speed limit?  -->
  <joint name="robot_joint5" type="revolute">
    <origin rpy="1.5707963267948966 0 0" xyz="0 0 0"/>
    <parent link="robot_link4"/>
    <child link="robot_link5"/>
    <axis xyz="0 0 1"/>
    <limit effort="528" lower="-1.60" upper="1.85" velocity="1.623"/>
  </joint>
  <!-- link6 -->
  <link name="robot_link6"/>
  <!-- lower, upper, speed limit?  -->
  <joint name="robot_joint6" type="revolute">
    <origin rpy="1.5707963267948966 -1.5707963267948966 0" xyz="0.0 -0.120 0"/>
    <parent link="robot_link5"/>
    <child link="robot_link6"/>
    <axis xyz="0 0 1"/>
    <limit effort="84" lower="-2" upper="2" velocity="3.665"/>
  </joint>
  <!-- gripper -->
  <link name="robot_gripper">
    <visual>
      <geometry>
        <mesh filename="package://robot_description/meshes/visual/gripper.dae"/>
      </geometry>
    </visual>
    <collision>
      <geometry>
        <mesh filename="package://robot_description/meshes/collision/gripper.stl"/>
      </geometry>
    </collision>
    <!-- mass? -->
    <inertial>
      <origin rpy="0 0 0" xyz="0 0 0"/>
      <mass value="2.74"/>
      <inertia ixx="0.3" ixy="0.0" ixz="0.0" iyy="0.3" iyz="0.0" izz="0.3"/>
    </inertial>
  </link>
  <joint name="robot_joint7" type="fixed">
    <origin rpy="0 0 0" xyz="0.100 0.0 0.047"/>
    <parent link="robot_link6"/>
    <child link="robot_gripper"/>
    <axis xyz="0 0 1"/>
  </joint>
  <!-- grasping frame -->
  <link name="tcp"/>
  <joint name="tcp_joint" type="fixed">
    <origin rpy="0 0 0" xyz="0 0 0.06887"/>
    <parent link="robot_gripper"/>
    <child link="tcp"/>
    <axis xyz="0 0 1"/>
  </joint>
  <!--  <xacro:panda_gazebo robot_name="$(arg robot_name)" />-->
  <!--  <xacro:panda_transmission robot_name="$(arg robot_name)" load_hand="false" />-->
  <!-- end for simulation -->
</robot>
